<sdf version='1.7'>
  <world name='default'>
    <light name='sun' type='directional'>
      <cast_shadows>1</cast_shadows>
      <pose>0 0 10 0 -0 0</pose>
      <diffuse>0.8 0.8 0.8 1</diffuse>
      <specular>0.2 0.2 0.2 1</specular>
      <attenuation>
        <range>1000</range>
        <constant>0.9</constant>
        <linear>0.01</linear>
        <quadratic>0.001</quadratic>
      </attenuation>
      <direction>-0.5 0.1 -0.9</direction>
      <spot>
        <inner_angle>0</inner_angle>
        <outer_angle>0</outer_angle>
        <falloff>0</falloff>
      </spot>
    </light>
    <model name='ground_plane'>
      <static>1</static>
      <link name='link'>
        <collision name='collision'>
          <geometry>
            <plane>
              <normal>0 0 1</normal>
              <size>100 100</size>
            </plane>
          </geometry>
          <surface>
            <contact>
              <collide_bitmask>65535</collide_bitmask>
              <ode/>
            </contact>
            <friction>
              <ode>
                <mu>100</mu>
                <mu2>50</mu2>
              </ode>
              <torsional>
                <ode/>
              </torsional>
            </friction>
            <bounce/>
          </surface>
          <max_contacts>10</max_contacts>
        </collision>
        <visual name='visual'>
          <cast_shadows>0</cast_shadows>
          <geometry>
            <plane>
              <normal>0 0 1</normal>
              <size>100 100</size>
            </plane>
          </geometry>
          <material>
            <script>
              <uri>file://media/materials/scripts/gazebo.material</uri>
              <name>Gazebo/Grey</name>
            </script>
          </material>
        </visual>
        <self_collide>0</self_collide>
        <enable_wind>0</enable_wind>
        <kinematic>0</kinematic>
      </link>
    </model>
    <gravity>0 0 -9.8</gravity>
    <magnetic_field>6e-06 2.3e-05 -4.2e-05</magnetic_field>
    <atmosphere type='adiabatic'/>
    <physics type='ode'>
      <max_step_size>0.001</max_step_size>
      <real_time_factor>1</real_time_factor>
      <real_time_update_rate>1000</real_time_update_rate>
    </physics>
    <scene>
      <ambient>0.4 0.4 0.4 1</ambient>
      <background>0.7 0.7 0.7 1</background>
      <shadows>1</shadows>
    </scene>
    <wind/>
    <spherical_coordinates>
      <surface_model>EARTH_WGS84</surface_model>
      <latitude_deg>0</latitude_deg>
      <longitude_deg>0</longitude_deg>
      <elevation>0</elevation>
      <heading_deg>0</heading_deg>
    </spherical_coordinates>
    <state world_name='default'>
      <sim_time>4169 519000000</sim_time>
      <real_time>150 330909591</real_time>
      <wall_time>1619665276 238716619</wall_time>
      <iterations>149737</iterations>
      <model name='coke_can'>
        <pose>1.00133 -0.001281 -0.002778 -0.062309 0.00276 -0.000558</pose>
        <scale>1 1 1</scale>
        <link name='link'>
          <pose>1.00133 -0.001281 -0.002778 -0.062309 0.00276 -0.000558</pose>
          <velocity>0 0 0 0 -0 0</velocity>
          <acceleration>-0.045918 -0.063041 0.000257 1.09649 -0.805773 -0.078231</acceleration>
          <wrench>-0.017908 -0.024586 0.0001 0 -0 0</wrench>
        </link>
      </model>
      <model name='coke_can_clone'>
        <pose>2.02817 -0.002006 -0.002779 -0.06229 0.002771 -0.000558</pose>
        <scale>1 1 1</scale>
        <link name='link'>
          <pose>2.02817 -0.002006 -0.002779 -0.06229 0.002771 -0.000558</pose>
          <velocity>0 0 0 0 -0 0</velocity>
          <acceleration>-0.043173 -0.049566 -0.000248 0.861856 -0.758005 -0.077071</acceleration>
          <wrench>-0.016837 -0.019331 -9.7e-05 0 -0 0</wrench>
        </link>
      </model>
      <model name='coke_can_clone_0'>
        <pose>3.01974 -0.010578 -0.002748 -0.06041 0.004074 -0.000539</pose>
        <scale>1 1 1</scale>
        <link name='link'>
          <pose>3.01974 -0.010578 -0.002748 -0.06041 0.004074 -0.000539</pose>
          <velocity>0 0 0 0 -0 0</velocity>
          <acceleration>-0.01918 -0.041635 -0.000367 0.725599 -0.336393 -0.029994</acceleration>
          <wrench>-0.00748 -0.016238 -0.000143 0 -0 0</wrench>
        </link>
      </model>
      <model name='ground_plane'>
        <pose>0 0 0 0 -0 0</pose>
        <scale>1 1 1</scale>
        <link name='link'>
          <pose>0 0 0 0 -0 0</pose>
          <velocity>0 0 0 0 -0 0</velocity>
          <acceleration>0 0 0 0 -0 0</acceleration>
          <wrench>0 0 0 0 -0 0</wrench>
        </link>
      </model>
      <model name='six_wheel_robot'>
        <pose>0.008058 -0.009081 0.00051 1.1e-05 3.2e-05 -0.001612</pose>
        <scale>1 1 1</scale>
        <link name='chassis'>
          <pose>0.00806 -0.009082 0.05051 1.1e-05 3.2e-05 -0.001612</pose>
          <velocity>-0.000833 1e-06 0.000283 -5.4e-05 -0.00011 -6.1e-05</velocity>
          <acceleration>-0.000346 0.002497 0.296459 -0.02678 -0.018474 3.1e-05</acceleration>
          <wrench>-0.000519 0.003746 0.444689 0 -0 0</wrench>
        </link>
        <link name='left_back_wheel'>
          <pose>-0.08673 0.126071 0.036513 -1.57075 -0.550732 -0.001506</pose>
          <velocity>-0.000823 1e-05 0.000249 -9e-05 -0.02253 -6.1e-05</velocity>
          <acceleration>-0.001002 0.00684 -0.086307 -0.012934 -0.010619 2.9e-05</acceleration>
          <wrench>-2.8e-05 0.000192 -0.002417 0 -0 0</wrench>
        </link>
        <link name='left_center_wheel'>
          <pose>0.00827 0.125918 0.036513 -1.57075 -0.550888 -0.001506</pose>
          <velocity>-0.000822 3e-06 0.000415 -9.5e-05 -0.022515 -6.1e-05</velocity>
          <acceleration>0.001733 0.00752 1.15311 -0.05549 -0.147155 2.9e-05</acceleration>
          <wrench>4.9e-05 0.000211 0.032287 0 -0 0</wrench>
        </link>
        <link name='left_front_wheel'>
          <pose>0.10327 0.125765 0.036506 -1.57076 -0.635227 -0.0015</pose>
          <velocity>-0.000823 -6e-06 0.00028 -0.000111 -0.035361 -6.1e-05</velocity>
          <acceleration>-0.000137 0.00212 0.285603 -0.026724 -0.011011 3.2e-05</acceleration>
          <wrench>-4e-06 5.9e-05 0.007997 0 -0 0</wrench>
        </link>
        <link name='right_back_wheel'>
          <pose>-0.087151 -0.143928 0.036512 -1.57075 -0.564737 -0.001505</pose>
          <velocity>-0.000839 4e-06 -0.000164 -9.9e-05 -0.022997 -6.1e-05</velocity>
          <acceleration>3.8e-05 0.00133 -0.283934 -0.035993 0.010272 3.3e-05</acceleration>
          <wrench>1e-06 3.7e-05 -0.00795 0 -0 0</wrench>
        </link>
        <link name='right_center_wheel'>
          <pose>0.007849 -0.144082 0.036513 -1.57075 -0.56512 -0.001505</pose>
          <velocity>-0.00084 3e-06 0.000172 -9.3e-05 -0.023013 -6.1e-05</velocity>
          <acceleration>-0.001911 0.006259 0.669958 -0.020198 0.140397 3.6e-05</acceleration>
          <wrench>-5.4e-05 0.000175 0.018759 0 -0 0</wrench>
        </link>
        <link name='right_front_wheel'>
          <pose>0.102842 -0.144235 0.036506 -1.56918 1.50052 -8.8e-05</pose>
          <velocity>-0.000839 -6e-06 0.000308 -3.7e-05 0.010367 -6.1e-05</velocity>
          <acceleration>-4.4e-05 0.002102 0.297917 -0.027016 -0.007769 2.8e-05</acceleration>
          <wrench>-1e-06 5.9e-05 0.008342 0 -0 0</wrench>
        </link>
      </model>
      <light name='sun'>
        <pose>0 0 10 0 -0 0</pose>
      </light>
    </state>
    <gui fullscreen='0'>
      <camera name='user_camera'>
        <pose>-1.72414 -3.59883 3.57894 0 0.66598 0.915512</pose>
        <view_controller>orbit</view_controller>
        <projection_type>perspective</projection_type>
        <!--<track_visual>
          <name>six_wheel_robot</name>
          <static>1</static>
          <use_model_frame>1</use_model_frame>
          <xyz>-3 -2 3</xyz>
          <inherit_yaw>1</inherit_yaw>
        </track_visual> -->
      </camera>
    </gui>
    <model name='six_wheel_robot'>
      <static>0</static>
      <plugin name='robot_control' filename='libsix_wheel_robot_drivetrain.so'/>
      <link name='chassis'>
        <pose>0 0 0.05 0 -0 0</pose>
        <inertial>
          <mass>1.5</mass>
          <pose>-0.05 0 0 0 -0 0</pose>
          <inertia>
            <ixx>20</ixx>
            <ixy>0</ixy>
            <ixz>0</ixz>
            <iyy>20</iyy>
            <iyz>0</iyz>
            <izz>0.05</izz>
          </inertia>
        </inertial>
        <collision name='collision'>
          <geometry>
            <box>
              <size>0.2794 0.254 0.073</size>
            </box>
          </geometry>
          <max_contacts>10</max_contacts>
          <surface>
            <contact>
              <ode/>
            </contact>
            <bounce/>
            <friction>
              <torsional>
                <ode/>
              </torsional>
              <ode/>
            </friction>
          </surface>
        </collision>
        <visual name='visual'>
          <geometry>
            <box>
              <size>0.2794 0.254 0.073</size>
            </box>
          </geometry>
        </visual>
        <self_collide>0</self_collide>
        <enable_wind>0</enable_wind>
        <kinematic>0</kinematic>
      </link>
      <link name='left_back_wheel'>
        <pose>-0.095 0.135 0.036 -0 1.5707 1.5707</pose>
        <inertial>
          <mass>0.028</mass>
          <inertia>
            <ixx>0.01</ixx>
            <ixy>0</ixy>
            <ixz>0</ixz>
            <iyy>0.01</iyy>
            <iyz>0</iyz>
            <izz>0.001</izz>
          </inertia>
          <pose>0 0 0 0 -0 0</pose>
        </inertial>
        <collision name='collision'>
          <geometry>
            <cylinder>
              <radius>0.0365125</radius>
              <length>0.00635</length>
            </cylinder>
          </geometry>
          <max_contacts>10</max_contacts>
          <surface>
            <contact>
              <ode/>
            </contact>
            <bounce/>
            <friction>
              <torsional>
                <ode/>
              </torsional>
              <ode/>
            </friction>
          </surface>
        </collision>
        <visual name='visual'>
          <geometry>
            <cylinder>
              <radius>0.0365125</radius>
              <length>0.00635</length>
            </cylinder>
          </geometry>
          <material>
            <ambient>0 0.9 0 1</ambient>
            <diffuse>0 0.9 0 1</diffuse>
            <specular>0 0 0 0</specular>
            <emissive>0 0 0 1</emissive>
          </material>
        </visual>
        <self_collide>0</self_collide>
        <enable_wind>0</enable_wind>
        <kinematic>0</kinematic>
      </link>
      <joint name='left_back_wheel_hinge' type='revolute'>
        <pose>0 0 -0.03 0 -0 0</pose>
        <child>left_back_wheel</child>
        <parent>chassis</parent>
        <axis>
          <xyz expressed_in='__model__'>0 1 0</xyz>
          <limit>
            <lower>-1e+16</lower>
            <upper>1e+16</upper>
          </limit>
          <dynamics>
            <spring_reference>0</spring_reference>
            <spring_stiffness>0</spring_stiffness>
          </dynamics>
        </axis>
      </joint>
      <link name='left_center_wheel'>
        <pose>0 0.135 0.036 -0 1.5707 1.5707</pose>
        <inertial>
          <mass>0.028</mass>
          <inertia>
            <ixx>0.01</ixx>
            <ixy>0</ixy>
            <ixz>0</ixz>
            <iyy>0.01</iyy>
            <iyz>0</iyz>
            <izz>0.001</izz>
          </inertia>
          <pose>0 0 0 0 -0 0</pose>
        </inertial>
        <collision name='collision'>
          <geometry>
            <cylinder>
              <radius>0.0365125</radius>
              <length>0.00635</length>
            </cylinder>
          </geometry>
          <max_contacts>10</max_contacts>
          <surface>
            <contact>
              <ode/>
            </contact>
            <bounce/>
            <friction>
              <torsional>
                <ode/>
              </torsional>
              <ode/>
            </friction>
          </surface>
        </collision>
        <visual name='visual'>
          <geometry>
            <cylinder>
              <radius>0.0365125</radius>
              <length>0.00635</length>
            </cylinder>
          </geometry>
          <material>
            <ambient>0 0.9 0 1</ambient>
            <diffuse>0 0.9 0 1</diffuse>
            <specular>0 0 0 0</specular>
            <emissive>0 0 0 1</emissive>
          </material>
        </visual>
        <self_collide>0</self_collide>
        <enable_wind>0</enable_wind>
        <kinematic>0</kinematic>
      </link>
      <joint name='left_center_wheel_hinge' type='revolute'>
        <pose>0 0 -0.03 0 -0 0</pose>
        <child>left_center_wheel</child>
        <parent>chassis</parent>
        <axis>
          <xyz expressed_in='__model__'>0 1 0</xyz>
          <limit>
            <lower>-1e+16</lower>
            <upper>1e+16</upper>
          </limit>
          <dynamics>
            <spring_reference>0</spring_reference>
            <spring_stiffness>0</spring_stiffness>
          </dynamics>
        </axis>
      </joint>
      <link name='left_front_wheel'>
        <pose>0.095 0.135 0.036 -0 1.5707 1.5707</pose>
        <inertial>
          <mass>0.028</mass>
          <inertia>
            <ixx>0.01</ixx>
            <ixy>0</ixy>
            <ixz>0</ixz>
            <iyy>0.01</iyy>
            <iyz>0</iyz>
            <izz>0.001</izz>
          </inertia>
          <pose>0 0 0 0 -0 0</pose>
        </inertial>
        <collision name='collision'>
          <geometry>
            <cylinder>
              <radius>0.03</radius>
              <length>0.00635</length>
            </cylinder>
          </geometry>
          <max_contacts>10</max_contacts>
          <surface>
            <contact>
              <ode/>
            </contact>
            <bounce/>
            <friction>
              <torsional>
                <ode/>
              </torsional>
              <ode/>
            </friction>
          </surface>
        </collision>
        <visual name='visual'>
          <geometry>
            <cylinder>
              <radius>0.03</radius>
              <length>0.00635</length>
            </cylinder>
          </geometry>
          <material>
            <ambient>0 0.9 0 1</ambient>
            <diffuse>0 0.9 0 1</diffuse>
            <specular>0 0 0 0</specular>
            <emissive>0 0 0 1</emissive>
          </material>
        </visual>
        <self_collide>0</self_collide>
        <enable_wind>0</enable_wind>
        <kinematic>0</kinematic>
      </link>
      <joint name='left_front_wheel_hinge' type='revolute'>
        <pose>0 0 -0.03 0 -0 0</pose>
        <child>left_front_wheel</child>
        <parent>chassis</parent>
        <axis>
          <xyz expressed_in='__model__'>0 1 0</xyz>
          <limit>
            <lower>-1e+16</lower>
            <upper>1e+16</upper>
          </limit>
          <dynamics>
            <spring_reference>0</spring_reference>
            <spring_stiffness>0</spring_stiffness>
          </dynamics>
        </axis>
      </joint>
      <link name='right_back_wheel'>
        <pose>-0.095 -0.135 0.036 -0 1.5707 1.5707</pose>
        <inertial>
          <mass>0.028</mass>
          <inertia>
            <ixx>0.01</ixx>
            <ixy>0</ixy>
            <ixz>0</ixz>
            <iyy>0.01</iyy>
            <iyz>0</iyz>
            <izz>0.001</izz>
          </inertia>
          <pose>0 0 0 0 -0 0</pose>
        </inertial>
        <collision name='collision'>
          <geometry>
            <cylinder>
              <radius>0.0365125</radius>
              <length>0.00635</length>
            </cylinder>
          </geometry>
          <max_contacts>10</max_contacts>
          <surface>
            <contact>
              <ode/>
            </contact>
            <bounce/>
            <friction>
              <torsional>
                <ode/>
              </torsional>
              <ode/>
            </friction>
          </surface>
        </collision>
        <visual name='visual'>
          <geometry>
            <cylinder>
              <radius>0.0365125</radius>
              <length>0.00635</length>
            </cylinder>
          </geometry>
          <material>
            <ambient>0 0.9 0 1</ambient>
            <diffuse>0 0.9 0 1</diffuse>
            <specular>0 0 0 0</specular>
            <emissive>0 0 0 1</emissive>
          </material>
        </visual>
        <self_collide>0</self_collide>
        <enable_wind>0</enable_wind>
        <kinematic>0</kinematic>
      </link>
      <joint name='right_back_wheel_hinge' type='revolute'>
        <pose>0 0 0.03 0 -0 0</pose>
        <child>right_back_wheel</child>
        <parent>chassis</parent>
        <axis>
          <xyz expressed_in='__model__'>0 1 0</xyz>
          <limit>
            <lower>-1e+16</lower>
            <upper>1e+16</upper>
          </limit>
          <dynamics>
            <spring_reference>0</spring_reference>
            <spring_stiffness>0</spring_stiffness>
          </dynamics>
        </axis>
      </joint>
      <link name='right_center_wheel'>
        <pose>0 -0.135 0.036 -0 1.5707 1.5707</pose>
        <inertial>
          <mass>0.028</mass>
          <inertia>
            <ixx>0.01</ixx>
            <ixy>0</ixy>
            <ixz>0</ixz>
            <iyy>0.01</iyy>
            <iyz>0</iyz>
            <izz>0.001</izz>
          </inertia>
          <pose>0 0 0 0 -0 0</pose>
        </inertial>
        <collision name='collision'>
          <geometry>
            <cylinder>
              <radius>0.0365125</radius>
              <length>0.00635</length>
            </cylinder>
          </geometry>
          <max_contacts>10</max_contacts>
          <surface>
            <contact>
              <ode/>
            </contact>
            <bounce/>
            <friction>
              <torsional>
                <ode/>
              </torsional>
              <ode/>
            </friction>
          </surface>
        </collision>
        <visual name='visual'>
          <geometry>
            <cylinder>
              <radius>0.0365125</radius>
              <length>0.00635</length>
            </cylinder>
          </geometry>
          <material>
            <ambient>0 0.9 0 1</ambient>
            <diffuse>0 0.9 0 1</diffuse>
            <specular>0 0 0 0</specular>
            <emissive>0 0 0 1</emissive>
          </material>
        </visual>
        <self_collide>0</self_collide>
        <enable_wind>0</enable_wind>
        <kinematic>0</kinematic>
      </link>
      <joint name='right_center_wheel_hinge' type='revolute'>
        <pose>0 0 0.03 0 -0 0</pose>
        <child>right_center_wheel</child>
        <parent>chassis</parent>
        <axis>
          <xyz expressed_in='__model__'>0 1 0</xyz>
          <limit>
            <lower>-1e+16</lower>
            <upper>1e+16</upper>
          </limit>
          <dynamics>
            <spring_reference>0</spring_reference>
            <spring_stiffness>0</spring_stiffness>
          </dynamics>
        </axis>
      </joint>
      <link name='right_front_wheel'>
        <pose>0.095 -0.135 0.036 -0 1.5707 1.5707</pose>
        <inertial>
          <mass>0.028</mass>
          <inertia>
            <ixx>0.01</ixx>
            <ixy>0</ixy>
            <ixz>0</ixz>
            <iyy>0.01</iyy>
            <iyz>0</iyz>
            <izz>0.001</izz>
          </inertia>
          <pose>0 0 0 0 -0 0</pose>
        </inertial>
        <collision name='collision'>
          <geometry>
            <cylinder>
              <radius>0.03</radius>
              <length>0.00635</length>
            </cylinder>
          </geometry>
          <max_contacts>10</max_contacts>
          <surface>
            <contact>
              <ode/>
            </contact>
            <bounce/>
            <friction>
              <torsional>
                <ode/>
              </torsional>
              <ode/>
            </friction>
          </surface>
        </collision>
        <visual name='visual'>
          <geometry>
            <cylinder>
              <radius>0.03</radius>
              <length>0.00635</length>
            </cylinder>
          </geometry>
          <material>
            <ambient>0 0.9 0 1</ambient>
            <diffuse>0 0.9 0 1</diffuse>
            <specular>0 0 0 0</specular>
            <emissive>0 0 0 1</emissive>
          </material>
        </visual>
        <self_collide>0</self_collide>
        <enable_wind>0</enable_wind>
        <kinematic>0</kinematic>
      </link>
      <joint name='right_front_wheel_hinge' type='revolute'>
        <pose>0 0 0.03 0 -0 0</pose>
        <child>right_front_wheel</child>
        <parent>chassis</parent>
        <axis>
          <xyz expressed_in='__model__'>0 1 0</xyz>
          <limit>
            <lower>-1e+16</lower>
            <upper>1e+16</upper>
          </limit>
          <dynamics>
            <spring_reference>0</spring_reference>
            <spring_stiffness>0</spring_stiffness>
          </dynamics>
        </axis>
      </joint>
      <pose>-0.014029 0.042908 0 0 -0 0</pose>
    </model>
    <model name='coke_can'>
      <link name='link'>
        <inertial>
          <pose>0 0 0.06 0 -0 0</pose>
          <mass>0.39</mass>
          <inertia>
            <ixx>0.00055575</ixx>
            <ixy>0</ixy>
            <ixz>0</ixz>
            <iyy>0.00055575</iyy>
            <iyz>0</iyz>
            <izz>0.0001755</izz>
          </inertia>
        </inertial>
        <collision name='collision'>
          <pose>0.003937 0.004724 -0.18 0 -0 0</pose>
          <geometry>
            <mesh>
              <uri>model://coke_can/meshes/coke_can.dae</uri>
            </mesh>
          </geometry>
          <surface>
            <friction>
              <ode>
                <mu>1</mu>
                <mu2>1</mu2>
              </ode>
              <torsional>
                <ode/>
              </torsional>
            </friction>
            <contact>
              <ode>
                <kp>1e+07</kp>
                <kd>1</kd>
                <min_depth>0.001</min_depth>
                <max_vel>0.1</max_vel>
              </ode>
            </contact>
            <bounce/>
          </surface>
          <max_contacts>10</max_contacts>
        </collision>
        <visual name='visual'>
          <pose>0.003937 0.004724 -0.18 0 -0 0</pose>
          <geometry>
            <mesh>
              <uri>model://coke_can/meshes/coke_can.dae</uri>
            </mesh>
          </geometry>
        </visual>
        <self_collide>0</self_collide>
        <enable_wind>0</enable_wind>
        <kinematic>0</kinematic>
      </link>
      <pose>1.00134 -0.001125 0 0 -0 0</pose>
    </model>
    <model name='coke_can_clone'>
      <link name='link'>
        <inertial>
          <pose>0 0 0.06 0 -0 0</pose>
          <mass>0.39</mass>
          <inertia>
            <ixx>0.00055575</ixx>
            <ixy>0</ixy>
            <ixz>0</ixz>
            <iyy>0.00055575</iyy>
            <iyz>0</iyz>
            <izz>0.0001755</izz>
          </inertia>
        </inertial>
        <collision name='collision'>
          <pose>0.003937 0.004724 -0.18 0 -0 0</pose>
          <geometry>
            <mesh>
              <uri>model://coke_can/meshes/coke_can.dae</uri>
            </mesh>
          </geometry>
          <surface>
            <friction>
              <ode>
                <mu>1</mu>
                <mu2>1</mu2>
              </ode>
              <torsional>
                <ode/>
              </torsional>
            </friction>
            <contact>
              <ode>
                <kp>1e+07</kp>
                <kd>1</kd>
                <min_depth>0.001</min_depth>
                <max_vel>0.1</max_vel>
              </ode>
            </contact>
            <bounce/>
          </surface>
          <max_contacts>10</max_contacts>
        </collision>
        <visual name='visual'>
          <pose>0.003937 0.004724 -0.18 0 -0 0</pose>
          <geometry>
            <mesh>
              <uri>model://coke_can/meshes/coke_can.dae</uri>
            </mesh>
          </geometry>
        </visual>
        <self_collide>0</self_collide>
        <enable_wind>0</enable_wind>
        <kinematic>0</kinematic>
      </link>
      <pose>2.02816 -0.001988 -0.002659 -0.055098 0.007752 -0.000483</pose>
    </model>
    <model name='coke_can_clone_0'>
      <link name='link'>
        <inertial>
          <pose>0 0 0.06 0 -0 0</pose>
          <mass>0.39</mass>
          <inertia>
            <ixx>0.00055575</ixx>
            <ixy>0</ixy>
            <ixz>0</ixz>
            <iyy>0.00055575</iyy>
            <iyz>0</iyz>
            <izz>0.0001755</izz>
          </inertia>
        </inertial>
        <collision name='collision'>
          <pose>0.003937 0.004724 -0.18 0 -0 0</pose>
          <geometry>
            <mesh>
              <uri>model://coke_can/meshes/coke_can.dae</uri>
            </mesh>
          </geometry>
          <surface>
            <friction>
              <ode>
                <mu>1</mu>
                <mu2>1</mu2>
              </ode>
              <torsional>
                <ode/>
              </torsional>
            </friction>
            <contact>
              <ode>
                <kp>1e+07</kp>
                <kd>1</kd>
                <min_depth>0.001</min_depth>
                <max_vel>0.1</max_vel>
              </ode>
            </contact>
            <bounce/>
          </surface>
          <max_contacts>10</max_contacts>
        </collision>
        <visual name='visual'>
          <pose>0.003937 0.004724 -0.18 0 -0 0</pose>
          <geometry>
            <mesh>
              <uri>model://coke_can/meshes/coke_can.dae</uri>
            </mesh>
          </geometry>
        </visual>
        <self_collide>0</self_collide>
        <enable_wind>0</enable_wind>
        <kinematic>0</kinematic>
      </link>
      <pose>3.01973 -0.010564 -0.002659 -0.055098 0.007752 -0.000483</pose>
    </model>
  </world>
</sdf>
