<sdf version='1.7'>
  <world name='default'>
    <light name='sun' type='directional'>
      <cast_shadows>1</cast_shadows>
      <pose>0 0 10 0 -0 0</pose>
      <diffuse>0.8 0.8 0.8 1</diffuse>
      <specular>0.2 0.2 0.2 1</specular>
      <attenuation>
        <range>1000</range>
        <constant>0.9</constant>
        <linear>0.01</linear>
        <quadratic>0.001</quadratic>
      </attenuation>
      <direction>-0.5 0.1 -0.9</direction>
      <spot>
        <inner_angle>0</inner_angle>
        <outer_angle>0</outer_angle>
        <falloff>0</falloff>
      </spot>
    </light>
    <model name='ground_plane'>
      <static>1</static>
      <link name='link'>
        <collision name='collision'>
          <geometry>
            <plane>
              <normal>0 0 1</normal>
              <size>100 100</size>
            </plane>
          </geometry>
          <surface>
            <contact>
              <collide_bitmask>65535</collide_bitmask>
              <ode/>
            </contact>
            <friction>
              <ode>
                <mu>100</mu>
                <mu2>50</mu2>
              </ode>
              <torsional>
                <ode/>
              </torsional>
            </friction>
            <bounce/>
          </surface>
          <max_contacts>10</max_contacts>
        </collision>
        <visual name='visual'>
          <cast_shadows>0</cast_shadows>
          <geometry>
            <plane>
              <normal>0 0 1</normal>
              <size>100 100</size>
            </plane>
          </geometry>
          <material>
            <script>
              <uri>file://media/materials/scripts/gazebo.material</uri>
              <name>Gazebo/Grey</name>
            </script>
          </material>
        </visual>
        <self_collide>0</self_collide>
        <enable_wind>0</enable_wind>
        <kinematic>0</kinematic>
      </link>
    </model>
    <gravity>0 0 -9.8</gravity>
    <magnetic_field>6e-06 2.3e-05 -4.2e-05</magnetic_field>
    <atmosphere type='adiabatic'/>
    <physics type='ode'>
      <max_step_size>0.001</max_step_size>
      <real_time_factor>1</real_time_factor>
      <real_time_update_rate>1000</real_time_update_rate>
    </physics>
    <scene>
      <ambient>0.4 0.4 0.4 1</ambient>
      <background>0.7 0.7 0.7 1</background>
      <shadows>1</shadows>
    </scene>
    <wind/>
    <spherical_coordinates>
      <surface_model>EARTH_WGS84</surface_model>
      <latitude_deg>0</latitude_deg>
      <longitude_deg>0</longitude_deg>
      <elevation>0</elevation>
      <heading_deg>0</heading_deg>
    </spherical_coordinates>
    <state world_name='default'>
      <sim_time>4201 463000000</sim_time>
      <real_time>31 967816762</real_time>
      <wall_time>1619915339 209462655</wall_time>
      <iterations>31944</iterations>
      <model name='coke_can'>
        <pose>1.00134 -0.001286 -0.002853 -0.064243 -0.002943 -0.000579</pose>
        <scale>1 1 1</scale>
        <link name='link'>
          <pose>1.00134 -0.001286 -0.002853 -0.064243 -0.002943 -0.000579</pose>
          <velocity>0 0 0 0 -0 0</velocity>
          <acceleration>-4e-06 -4e-06 -1e-06 7.1e-05 -6.7e-05 -3.1e-05</acceleration>
          <wrench>-2e-06 -2e-06 -0 0 -0 0</wrench>
        </link>
      </model>
      <model name='coke_can_clone'>
        <pose>5.01232 -0.003615 -0.002596 -0.018859 0.00315 0.000844</pose>
        <scale>1 1 1</scale>
        <link name='link'>
          <pose>5.01232 -0.003615 -0.002596 -0.018859 0.00315 0.000844</pose>
          <velocity>0 0 0 0 -0 0</velocity>
          <acceleration>-0.069563 -0.194221 -0.006223 -2.90226 -1.21168 -0.014295</acceleration>
          <wrench>-0.027129 -0.075746 -0.002427 0 -0 0</wrench>
        </link>
      </model>
      <model name='coke_can_clone_0'>
        <pose>3.01975 -0.010588 -0.00281 -0.064299 -0.000263 -0.000583</pose>
        <scale>1 1 1</scale>
        <link name='link'>
          <pose>3.01975 -0.010588 -0.00281 -0.064299 -0.000263 -0.000583</pose>
          <velocity>0 0 0 0 -0 0</velocity>
          <acceleration>-4e-06 -4e-06 -1e-06 6.4e-05 -6.3e-05 -6e-06</acceleration>
          <wrench>-1e-06 -1e-06 -0 0 -0 0</wrench>
        </link>
      </model>
      <model name='ground_plane'>
        <pose>0 0 0 0 -0 0</pose>
        <scale>1 1 1</scale>
        <link name='link'>
          <pose>0 0 0 0 -0 0</pose>
          <velocity>0 0 0 0 -0 0</velocity>
          <acceleration>0 0 0 0 -0 0</acceleration>
          <wrench>0 0 0 0 -0 0</wrench>
        </link>
      </model>
      <model name='six_wheel_robot'>
        <pose>-0.034008 -0.009028 0.000512 4.2e-05 8e-06 -0.003094</pose>
        <scale>1 1 1</scale>
        <link name='chassis'>
          <pose>-0.034008 -0.00903 0.050512 4.2e-05 8e-06 -0.003094</pose>
          <velocity>-0.001709 4e-06 0.004895 1e-06 -0 -2.3e-05</velocity>
          <acceleration>-2.7e-05 5.3e-05 9.78953 -0.000157 3.6e-05 -2.8e-05</acceleration>
          <wrench>-4e-05 7.9e-05 14.6843 0 -0 0</wrench>
        </link>
        <link name='left_back_wheel'>
          <pose>-0.128595 0.126264 0.036513 1.57132 -1.4447 3.13806</pose>
          <velocity>-0.001705 5e-06 0.005 -0.000142 -0.046697 -2.5e-05</velocity>
          <acceleration>0.000497 -0.00285 9.99952 0.00279 -0.007882 0</acceleration>
          <wrench>1.4e-05 -8e-05 0.279987 0 -0 0</wrench>
        </link>
        <link name='left_center_wheel'>
          <pose>-0.033595 0.12597 0.036513 1.57132 -1.44463 3.13806</pose>
          <velocity>-0.001705 5e-06 0.00515 -0.000148 -0.046696 -2.5e-05</velocity>
          <acceleration>0.000597 0.001917 10.3005 -0.009596 -0.007954 -2e-06</acceleration>
          <wrench>1.7e-05 5.4e-05 0.288414 0 -0 0</wrench>
        </link>
        <link name='left_front_wheel'>
          <pose>0.061406 0.125676 0.03651 1.57094 -0.86819 3.1384</pose>
          <velocity>-0.001705 2e-06 0.004888 -0.00019 -0.061815 -2.5e-05</velocity>
          <acceleration>-3.5e-05 4.7e-05 9.77569 1e-05 -0.001853 -4e-06</acceleration>
          <wrench>-1e-06 1e-06 0.273719 0 -0 0</wrench>
        </link>
        <link name='right_back_wheel'>
          <pose>-0.12942 -0.143735 0.036513 1.57125 -1.41858 3.13814</pose>
          <velocity>-0.001712 5e-06 0.004802 -0.000139 -0.046889 -2.5e-05</velocity>
          <acceleration>-0.000584 -0.00311 9.60358 0.010027 -0.007724 -1e-06</acceleration>
          <wrench>-1.6e-05 -8.7e-05 0.2689 0 -0 0</wrench>
        </link>
        <link name='right_center_wheel'>
          <pose>-0.03442 -0.144028 0.036513 1.57124 -1.41814 3.13814</pose>
          <velocity>-0.001712 5e-06 0.004952 -0.000138 -0.04689 -2.5e-05</velocity>
          <acceleration>-0.000667 0.001097 9.90448 0.012996 -0.007551 -3e-06</acceleration>
          <wrench>-1.9e-05 3.1e-05 0.277325 0 -0 0</wrench>
        </link>
        <link name='right_front_wheel'>
          <pose>0.060575 -0.144322 0.036505 -1.56967 1.43755 -0.002058</pose>
          <velocity>-0.001712 2e-06 0.004889 -4.3e-05 -0.014024 -2.3e-05</velocity>
          <acceleration>-3.4e-05 7e-05 9.7773 -0.000683 -0.0136 -6e-06</acceleration>
          <wrench>-1e-06 2e-06 0.273764 0 -0 0</wrench>
        </link>
      </model>
      <light name='sun'>
        <pose>0 0 10 0 -0 0</pose>
      </light>
    </state>
    <gui fullscreen='0'>
      <camera name='user_camera'>
        <pose>0.021133 -4.77726 3.98367 0 0.67398 1.12351</pose>
        <view_controller>orbit</view_controller>
        <projection_type>perspective</projection_type>
      </camera>
    </gui>
    <model name='six_wheel_robot'>
      <static>0</static>
      <plugin name='robot_control' filename='libsix_wheel_robot_drivetrain.so'/>
      <link name='chassis'>
        <pose>0 0 0.05 0 -0 0</pose>
        <inertial>
          <mass>1.5</mass>
          <pose>-0.05 0 0 0 -0 0</pose>
          <inertia>
            <ixx>20</ixx>
            <ixy>0</ixy>
            <ixz>0</ixz>
            <iyy>20</iyy>
            <iyz>0</iyz>
            <izz>0.05</izz>
          </inertia>
        </inertial>
        <collision name='collision'>
          <geometry>
            <box>
              <size>0.2794 0.254 0.073</size>
            </box>
          </geometry>
          <max_contacts>10</max_contacts>
          <surface>
            <contact>
              <ode/>
            </contact>
            <bounce/>
            <friction>
              <torsional>
                <ode/>
              </torsional>
              <ode/>
            </friction>
          </surface>
        </collision>
        <visual name='visual'>
          <geometry>
            <box>
              <size>0.2794 0.254 0.073</size>
            </box>
          </geometry>
        </visual>
        <self_collide>0</self_collide>
        <enable_wind>0</enable_wind>
        <kinematic>0</kinematic>
      </link>
      <link name='left_back_wheel'>
        <pose>-0.095 0.135 0.036 -0 1.5707 1.5707</pose>
        <inertial>
          <mass>0.028</mass>
          <inertia>
            <ixx>0.01</ixx>
            <ixy>0</ixy>
            <ixz>0</ixz>
            <iyy>0.01</iyy>
            <iyz>0</iyz>
            <izz>0.001</izz>
          </inertia>
          <pose>0 0 0 0 -0 0</pose>
        </inertial>
        <collision name='collision'>
          <geometry>
            <cylinder>
              <radius>0.0365125</radius>
              <length>0.00635</length>
            </cylinder>
          </geometry>
          <max_contacts>10</max_contacts>
          <surface>
            <contact>
              <ode/>
            </contact>
            <bounce/>
            <friction>
              <torsional>
                <ode/>
              </torsional>
              <ode/>
            </friction>
          </surface>
        </collision>
        <visual name='visual'>
          <geometry>
            <cylinder>
              <radius>0.0365125</radius>
              <length>0.00635</length>
            </cylinder>
          </geometry>
          <material>
            <ambient>0 0.9 0 1</ambient>
            <diffuse>0 0.9 0 1</diffuse>
            <specular>0 0 0 0</specular>
            <emissive>0 0 0 1</emissive>
          </material>
        </visual>
        <self_collide>0</self_collide>
        <enable_wind>0</enable_wind>
        <kinematic>0</kinematic>
      </link>
      <joint name='left_back_wheel_hinge' type='revolute'>
        <pose>0 0 -0.03 0 -0 0</pose>
        <child>left_back_wheel</child>
        <parent>chassis</parent>
        <axis>
          <xyz expressed_in='__model__'>0 1 0</xyz>
          <limit>
            <lower>-1e+16</lower>
            <upper>1e+16</upper>
          </limit>
          <dynamics>
            <spring_reference>0</spring_reference>
            <spring_stiffness>0</spring_stiffness>
          </dynamics>
        </axis>
      </joint>
      <link name='left_center_wheel'>
        <pose>0 0.135 0.036 -0 1.5707 1.5707</pose>
        <inertial>
          <mass>0.028</mass>
          <inertia>
            <ixx>0.01</ixx>
            <ixy>0</ixy>
            <ixz>0</ixz>
            <iyy>0.01</iyy>
            <iyz>0</iyz>
            <izz>0.001</izz>
          </inertia>
          <pose>0 0 0 0 -0 0</pose>
        </inertial>
        <collision name='collision'>
          <geometry>
            <cylinder>
              <radius>0.0365125</radius>
              <length>0.00635</length>
            </cylinder>
          </geometry>
          <max_contacts>10</max_contacts>
          <surface>
            <contact>
              <ode/>
            </contact>
            <bounce/>
            <friction>
              <torsional>
                <ode/>
              </torsional>
              <ode/>
            </friction>
          </surface>
        </collision>
        <visual name='visual'>
          <geometry>
            <cylinder>
              <radius>0.0365125</radius>
              <length>0.00635</length>
            </cylinder>
          </geometry>
          <material>
            <ambient>0 0.9 0 1</ambient>
            <diffuse>0 0.9 0 1</diffuse>
            <specular>0 0 0 0</specular>
            <emissive>0 0 0 1</emissive>
          </material>
        </visual>
        <self_collide>0</self_collide>
        <enable_wind>0</enable_wind>
        <kinematic>0</kinematic>
      </link>
      <joint name='left_center_wheel_hinge' type='revolute'>
        <pose>0 0 -0.03 0 -0 0</pose>
        <child>left_center_wheel</child>
        <parent>chassis</parent>
        <axis>
          <xyz expressed_in='__model__'>0 1 0</xyz>
          <limit>
            <lower>-1e+16</lower>
            <upper>1e+16</upper>
          </limit>
          <dynamics>
            <spring_reference>0</spring_reference>
            <spring_stiffness>0</spring_stiffness>
          </dynamics>
        </axis>
      </joint>
      <link name='left_front_wheel'>
        <pose>0.095 0.135 0.036 -0 1.5707 1.5707</pose>
        <inertial>
          <mass>0.028</mass>
          <inertia>
            <ixx>0.01</ixx>
            <ixy>0</ixy>
            <ixz>0</ixz>
            <iyy>0.01</iyy>
            <iyz>0</iyz>
            <izz>0.001</izz>
          </inertia>
          <pose>0 0 0 0 -0 0</pose>
        </inertial>
        <collision name='collision'>
          <geometry>
            <cylinder>
              <radius>0.03</radius>
              <length>0.00635</length>
            </cylinder>
          </geometry>
          <max_contacts>10</max_contacts>
          <surface>
            <contact>
              <ode/>
            </contact>
            <bounce/>
            <friction>
              <torsional>
                <ode/>
              </torsional>
              <ode/>
            </friction>
          </surface>
        </collision>
        <visual name='visual'>
          <geometry>
            <cylinder>
              <radius>0.03</radius>
              <length>0.00635</length>
            </cylinder>
          </geometry>
          <material>
            <ambient>0 0.9 0 1</ambient>
            <diffuse>0 0.9 0 1</diffuse>
            <specular>0 0 0 0</specular>
            <emissive>0 0 0 1</emissive>
          </material>
        </visual>
        <self_collide>0</self_collide>
        <enable_wind>0</enable_wind>
        <kinematic>0</kinematic>
      </link>
      <joint name='left_front_wheel_hinge' type='revolute'>
        <pose>0 0 -0.03 0 -0 0</pose>
        <child>left_front_wheel</child>
        <parent>chassis</parent>
        <axis>
          <xyz expressed_in='__model__'>0 1 0</xyz>
          <limit>
            <lower>-1e+16</lower>
            <upper>1e+16</upper>
          </limit>
          <dynamics>
            <spring_reference>0</spring_reference>
            <spring_stiffness>0</spring_stiffness>
          </dynamics>
        </axis>
      </joint>
      <link name='right_back_wheel'>
        <pose>-0.095 -0.135 0.036 -0 1.5707 1.5707</pose>
        <inertial>
          <mass>0.028</mass>
          <inertia>
            <ixx>0.01</ixx>
            <ixy>0</ixy>
            <ixz>0</ixz>
            <iyy>0.01</iyy>
            <iyz>0</iyz>
            <izz>0.001</izz>
          </inertia>
          <pose>0 0 0 0 -0 0</pose>
        </inertial>
        <collision name='collision'>
          <geometry>
            <cylinder>
              <radius>0.0365125</radius>
              <length>0.00635</length>
            </cylinder>
          </geometry>
          <max_contacts>10</max_contacts>
          <surface>
            <contact>
              <ode/>
            </contact>
            <bounce/>
            <friction>
              <torsional>
                <ode/>
              </torsional>
              <ode/>
            </friction>
          </surface>
        </collision>
        <visual name='visual'>
          <geometry>
            <cylinder>
              <radius>0.0365125</radius>
              <length>0.00635</length>
            </cylinder>
          </geometry>
          <material>
            <ambient>0 0.9 0 1</ambient>
            <diffuse>0 0.9 0 1</diffuse>
            <specular>0 0 0 0</specular>
            <emissive>0 0 0 1</emissive>
          </material>
        </visual>
        <self_collide>0</self_collide>
        <enable_wind>0</enable_wind>
        <kinematic>0</kinematic>
      </link>
      <joint name='right_back_wheel_hinge' type='revolute'>
        <pose>0 0 0.03 0 -0 0</pose>
        <child>right_back_wheel</child>
        <parent>chassis</parent>
        <axis>
          <xyz expressed_in='__model__'>0 1 0</xyz>
          <limit>
            <lower>-1e+16</lower>
            <upper>1e+16</upper>
          </limit>
          <dynamics>
            <spring_reference>0</spring_reference>
            <spring_stiffness>0</spring_stiffness>
          </dynamics>
        </axis>
      </joint>
      <link name='right_center_wheel'>
        <pose>0 -0.135 0.036 -0 1.5707 1.5707</pose>
        <inertial>
          <mass>0.028</mass>
          <inertia>
            <ixx>0.01</ixx>
            <ixy>0</ixy>
            <ixz>0</ixz>
            <iyy>0.01</iyy>
            <iyz>0</iyz>
            <izz>0.001</izz>
          </inertia>
          <pose>0 0 0 0 -0 0</pose>
        </inertial>
        <collision name='collision'>
          <geometry>
            <cylinder>
              <radius>0.0365125</radius>
              <length>0.00635</length>
            </cylinder>
          </geometry>
          <max_contacts>10</max_contacts>
          <surface>
            <contact>
              <ode/>
            </contact>
            <bounce/>
            <friction>
              <torsional>
                <ode/>
              </torsional>
              <ode/>
            </friction>
          </surface>
        </collision>
        <visual name='visual'>
          <geometry>
            <cylinder>
              <radius>0.0365125</radius>
              <length>0.00635</length>
            </cylinder>
          </geometry>
          <material>
            <ambient>0 0.9 0 1</ambient>
            <diffuse>0 0.9 0 1</diffuse>
            <specular>0 0 0 0</specular>
            <emissive>0 0 0 1</emissive>
          </material>
        </visual>
        <self_collide>0</self_collide>
        <enable_wind>0</enable_wind>
        <kinematic>0</kinematic>
      </link>
      <joint name='right_center_wheel_hinge' type='revolute'>
        <pose>0 0 0.03 0 -0 0</pose>
        <child>right_center_wheel</child>
        <parent>chassis</parent>
        <axis>
          <xyz expressed_in='__model__'>0 1 0</xyz>
          <limit>
            <lower>-1e+16</lower>
            <upper>1e+16</upper>
          </limit>
          <dynamics>
            <spring_reference>0</spring_reference>
            <spring_stiffness>0</spring_stiffness>
          </dynamics>
        </axis>
      </joint>
      <link name='right_front_wheel'>
        <pose>0.095 -0.135 0.036 -0 1.5707 1.5707</pose>
        <inertial>
          <mass>0.028</mass>
          <inertia>
            <ixx>0.01</ixx>
            <ixy>0</ixy>
            <ixz>0</ixz>
            <iyy>0.01</iyy>
            <iyz>0</iyz>
            <izz>0.001</izz>
          </inertia>
          <pose>0 0 0 0 -0 0</pose>
        </inertial>
        <collision name='collision'>
          <geometry>
            <cylinder>
              <radius>0.03</radius>
              <length>0.00635</length>
            </cylinder>
          </geometry>
          <max_contacts>10</max_contacts>
          <surface>
            <contact>
              <ode/>
            </contact>
            <bounce/>
            <friction>
              <torsional>
                <ode/>
              </torsional>
              <ode/>
            </friction>
          </surface>
        </collision>
        <visual name='visual'>
          <geometry>
            <cylinder>
              <radius>0.03</radius>
              <length>0.00635</length>
            </cylinder>
          </geometry>
          <material>
            <ambient>0 0.9 0 1</ambient>
            <diffuse>0 0.9 0 1</diffuse>
            <specular>0 0 0 0</specular>
            <emissive>0 0 0 1</emissive>
          </material>
        </visual>
        <self_collide>0</self_collide>
        <enable_wind>0</enable_wind>
        <kinematic>0</kinematic>
      </link>
      <joint name='right_front_wheel_hinge' type='revolute'>
        <pose>0 0 0.03 0 -0 0</pose>
        <child>right_front_wheel</child>
        <parent>chassis</parent>
        <axis>
          <xyz expressed_in='__model__'>0 1 0</xyz>
          <limit>
            <lower>-1e+16</lower>
            <upper>1e+16</upper>
          </limit>
          <dynamics>
            <spring_reference>0</spring_reference>
            <spring_stiffness>0</spring_stiffness>
          </dynamics>
        </axis>
      </joint>
      <pose>-0.014029 0.042908 0 0 -0 0</pose>
    </model>
    <model name='coke_can'>
      <link name='link'>
        <inertial>
          <pose>0 0 0.06 0 -0 0</pose>
          <mass>0.39</mass>
          <inertia>
            <ixx>0.00055575</ixx>
            <ixy>0</ixy>
            <ixz>0</ixz>
            <iyy>0.00055575</iyy>
            <iyz>0</iyz>
            <izz>0.0001755</izz>
          </inertia>
        </inertial>
        <collision name='collision'>
          <pose>0.003937 0.004724 -0.18 0 -0 0</pose>
          <geometry>
            <mesh>
              <uri>model://coke_can/meshes/coke_can.dae</uri>
            </mesh>
          </geometry>
          <surface>
            <friction>
              <ode>
                <mu>1</mu>
                <mu2>1</mu2>
              </ode>
              <torsional>
                <ode/>
              </torsional>
            </friction>
            <contact>
              <ode>
                <kp>1e+07</kp>
                <kd>1</kd>
                <min_depth>0.001</min_depth>
                <max_vel>0.1</max_vel>
              </ode>
            </contact>
            <bounce/>
          </surface>
          <max_contacts>10</max_contacts>
        </collision>
        <visual name='visual'>
          <pose>0.003937 0.004724 -0.18 0 -0 0</pose>
          <geometry>
            <mesh>
              <uri>model://coke_can/meshes/coke_can.dae</uri>
            </mesh>
          </geometry>
        </visual>
        <self_collide>0</self_collide>
        <enable_wind>0</enable_wind>
        <kinematic>0</kinematic>
      </link>
      <pose>1.00134 -0.001125 0 0 -0 0</pose>
    </model>
    <model name='coke_can_clone'>
      <link name='link'>
        <inertial>
          <pose>0 0 0.06 0 -0 0</pose>
          <mass>0.39</mass>
          <inertia>
            <ixx>0.00055575</ixx>
            <ixy>0</ixy>
            <ixz>0</ixz>
            <iyy>0.00055575</iyy>
            <iyz>0</iyz>
            <izz>0.0001755</izz>
          </inertia>
        </inertial>
        <collision name='collision'>
          <pose>0.003937 0.004724 -0.18 0 -0 0</pose>
          <geometry>
            <mesh>
              <uri>model://coke_can/meshes/coke_can.dae</uri>
            </mesh>
          </geometry>
          <surface>
            <friction>
              <ode>
                <mu>1</mu>
                <mu2>1</mu2>
              </ode>
              <torsional>
                <ode/>
              </torsional>
            </friction>
            <contact>
              <ode>
                <kp>1e+07</kp>
                <kd>1</kd>
                <min_depth>0.001</min_depth>
                <max_vel>0.1</max_vel>
              </ode>
            </contact>
            <bounce/>
          </surface>
          <max_contacts>10</max_contacts>
        </collision>
        <visual name='visual'>
          <pose>0.003937 0.004724 -0.18 0 -0 0</pose>
          <geometry>
            <mesh>
              <uri>model://coke_can/meshes/coke_can.dae</uri>
            </mesh>
          </geometry>
        </visual>
        <self_collide>0</self_collide>
        <enable_wind>0</enable_wind>
        <kinematic>0</kinematic>
      </link>
      <pose>2.02816 -0.001988 -0.002659 -0.055098 0.007752 -0.000483</pose>
    </model>
    <model name='coke_can_clone_0'>
      <link name='link'>
        <inertial>
          <pose>0 0 0.06 0 -0 0</pose>
          <mass>0.39</mass>
          <inertia>
            <ixx>0.00055575</ixx>
            <ixy>0</ixy>
            <ixz>0</ixz>
            <iyy>0.00055575</iyy>
            <iyz>0</iyz>
            <izz>0.0001755</izz>
          </inertia>
        </inertial>
        <collision name='collision'>
          <pose>0.003937 0.004724 -0.18 0 -0 0</pose>
          <geometry>
            <mesh>
              <uri>model://coke_can/meshes/coke_can.dae</uri>
            </mesh>
          </geometry>
          <surface>
            <friction>
              <ode>
                <mu>1</mu>
                <mu2>1</mu2>
              </ode>
              <torsional>
                <ode/>
              </torsional>
            </friction>
            <contact>
              <ode>
                <kp>1e+07</kp>
                <kd>1</kd>
                <min_depth>0.001</min_depth>
                <max_vel>0.1</max_vel>
              </ode>
            </contact>
            <bounce/>
          </surface>
          <max_contacts>10</max_contacts>
        </collision>
        <visual name='visual'>
          <pose>0.003937 0.004724 -0.18 0 -0 0</pose>
          <geometry>
            <mesh>
              <uri>model://coke_can/meshes/coke_can.dae</uri>
            </mesh>
          </geometry>
        </visual>
        <self_collide>0</self_collide>
        <enable_wind>0</enable_wind>
        <kinematic>0</kinematic>
      </link>
      <pose>3.01973 -0.010564 -0.002659 -0.055098 0.007752 -0.000483</pose>
    </model>
  </world>
</sdf>
